<mujoco model="block_insert">
  <compiler inertiafromgeom="true" angle="radian" coordinate="local"/>
  <option timestep="0.01" gravity="0 0 0" iterations="20" integrator="RK4" />

  <default>
    <joint armature='0.04' damping="1" limited="true"/>
<!--    <geom friction=".8 .1 .1" density="300" margin="0.002" condim="1" contype="0" conaffinity="0"/>-->
      <geom friction=".8 .1 .1" margin="0.002" condim="1" contype="0" conaffinity="0"/>
  </default>

  <worldbody>
<!--    <light diffuse=".5 .5 .5" pos="0 0 3" dir="0 0 -1"/>-->
<!--    <geom name="table" type="plane" pos="0 0.5 -0.325" size="1 1 0.1" contype="1" conaffinity="1"/>-->
    <!-- <light cutoff="100" diffuse="1 1 1" dir="-0 0 -1.3" directional="true" exponent="1" pos="0 0 1.3" specular=".1 .1 .1"/> -->
  	<geom contype="1" conaffinity="0" condim="1" name="floor" pos="0 0 0" rgba="0.8 0.9 0.8 1" size="2 2 .1" type="plane" material="MatPlane"/>

   <body name="blockx" pos="0 0 0">
<!--       <body name="blockx" pos="0.4 -.1 0">-->
<!--      pos1-->
<!--      <body name="blockx" pos="0 -0.3 0">-->
<!--      pos 2-->
<!--      <body name="blockx" pos="0.3 -0.3 0">-->
          <!--      pos 3-->
<!--      <body name="blockx" pos="0.2 -0.3 0">-->
      <!--      pos 4 this is used for the final exp-->
<!--      <body name="blockx" pos="0.4 -0.6 0">-->
        <joint axis="1 0 0" limited="true" name="slidex" pos="0 0 0" range="0 1.0" damping="1" type="slide"/>
       <geom name="framex" pos="0 0 -0.002" rgba="0 0.7 0.7 1" size="0.001 0.001 0.001" mass ="0.001" contype="1" conaffinity="1" type="box"/>
			<body name="blocky" pos="0 0 0">
				<joint axis="0 1 0" limited="true" name="slidey" pos="0 0 0" range="-1.0 0.5" damping="1" type="slide"/>
				<geom name="framey" pos="0 0 0.05" rgba="0 0.7 0.7 1" size="0.05 0.04975 0.05" mass ="1" contype="1" conaffinity="0" friction=".5 0.01 0.01" type="box"/>
               <!-- <geom name="framey" pos="0 0 0.05" rgba="0 0.7 0.7 1" size="0.05 0.048 0.05" mass ="1" contype="1" conaffinity="0" friction=".5 0.01 0.01" type="box"/> -->
<!--                <geom name="framey" pos="0 0 0.05" rgba="0 0.7 0.7 1" size="0.05 0.05 0.05" mass ="2" contype="1" conaffinity="0" friction=".5 0.01 0.01" type="box"/>-->
			</body>
    </body>

  <body name="fl1" pos="0 0 0">
      <!-- this is for bullet import, mujoco treat unspecified joint as fixed by default -->
      <joint name="fixedfl1" axis="1 0 0"  limited="true" pos="0 0 0" range="0 1.0" damping="1" type="fixed"/>
      <geom name="fl1" pos="0.4 0.05 0.05" rgba="0.3 0.5 0.6 1" type="box" size="0.05 0.1 0.05" contype="1" conaffinity="1" friction=".1 0.01 0.01" />
<!--      <geom name="fl1" pos="0.4 0.055 0.05" rgba="0.3 0.5 0.6 1" type="box" size="0.05 0.1 0.05" contype="1" conaffinity="1" friction=".1 0.01 0.01" />-->
    </body>
  <body name="fl2" pos="0 0 0">
    <!-- this is for bullet import, mujoco treat unspecified joint as fixed by default -->
    <joint name="fixedfl2" axis="1 0 0"  limited="true" pos="0 0 0" range="0 1.0" damping="1" type="fixed"/>
    <geom name="fl2" pos="0.4 -0.25 0.05" rgba="0.3 0.5 0.6 1" type="box" size="0.05 0.1 0.05" contype="1" conaffinity="1" friction=".1 0.01 0.01" />
<!--      <geom name="fl2" pos="0.4 -0.255 0.05" rgba="0.3 0.5 0.6 1" type="box" size="0.05 0.1 0.05" contype="1" conaffinity="1" friction=".1 0.01 0.01" />-->
    </body>
    <body name="fl3" pos="0 0 0">
      <!-- this is for bullet import, mujoco treat unspecified joint as fixed by default -->
      <joint name="fixedfl3" axis="1 0 0"  limited="true" pos="0 0 0" range="0 1.0" damping="1" type="fixed"/>
    <geom name="fl3" pos="0.5 -0.10 0.05" rgba="0.3 0.5 0.6 1" type="box" size="0.05 0.25 0.05" contype="1" conaffinity="1" friction=".1 0.01 0.01" />
    </body>
  </worldbody>

    <!-- ======================Visualizing the world================================== -->
    <asset>
        <texture type="skybox" builtin="gradient" rgb1=".4 .5 .6" rgb2="0 0 0"
            width="100" height="100"/>
        <texture builtin="flat" height="1278" mark="cross" markrgb="1 1 1" name="texgeom" random="0.01" rgb1="0.8 0.6 0.4" rgb2="0.8 0.6 0.4" type="cube" width="127"/>
        <texture builtin="checker" height="100" name="texplane" rgb1="0 0 0" rgb2="0.8 0.8 0.8" type="2d" width="100"/>
        <material name="MatPlane" reflectance="0.01" shininess="1" specular="1" texrepeat="60 60" texture="texplane"/>
        <material name="geom" texture="texgeom" texuniform="true"/>
    </asset>

  <actuator>
    <motor gear="1" joint="slidex" ctrlrange="-10.0 10.0" ctrllimited="false"/>
    <motor gear="1" joint="slidey" ctrlrange="-10.0 10.0" ctrllimited="false"/>
  </actuator>
</mujoco>